Workbook
Name bandera: INDEX(Hoja1!$D$6:$E$56,MATCH(FINAL!$Q$16,Hoja1!$D$6:$D$56,0),2)
Name CFcuatro: INDEX(Hoja1!$D$6:$E$120,MATCH('Cuartos de Final'!$K$19,Hoja1!$D$6:$D$120,0),2)
Name CFdos: INDEX(Hoja1!$D$6:$E$120,MATCH('Cuartos de Final'!$K$11,Hoja1!$D$6:$D$120,0),2)
Name CFtres: INDEX(Hoja1!$D$6:$E$120,MATCH('Cuartos de Final'!$K$15,Hoja1!$D$6:$D$120,0),2)
Name CFuno: INDEX(Hoja1!$D$6:$E$120,MATCH('Cuartos de Final'!$K$7,Hoja1!$D$6:$D$120,0),2)
Name copa: INDEX(Hoja1!$A$2:$B$5,MATCH(FINAL!$P$16,Hoja1!$A$2:$A$5,0),2)
Name dcatorce: INDEX(Hoja1!$D$6:$E$120,MATCH('16vos de Final'!$K$59,Hoja1!$D$6:$D$120,0),2)
Name ddiesies: INDEX(Hoja1!$D$6:$E$120,MATCH('16vos de Final'!$K$67,Hoja1!$D$6:$D$120,0),2)
Name ddiez: INDEX(Hoja1!$D$6:$E$120,MATCH('16vos de Final'!$K$43,Hoja1!$D$6:$D$120,0),2)
Name ddoce: INDEX(Hoja1!$D$6:$E$120,MATCH('16vos de Final'!$K$51,Hoja1!$D$6:$D$120,0),2)
Name donce: INDEX(Hoja1!$D$6:$E$120,MATCH('16vos de Final'!$K$47,Hoja1!$D$6:$D$120,0),2)
Name dquince: INDEX(Hoja1!$D$6:$E$120,MATCH('16vos de Final'!$K$63,Hoja1!$D$6:$D$120,0),2)
Name dtrece: INDEX(Hoja1!$D$6:$E$120,MATCH('16vos de Final'!$K$55,Hoja1!$D$6:$D$120,0),2)
Name OFcinco: INDEX(Hoja1!$D$6:$E$120,MATCH('16vos de Final'!$K$23,Hoja1!$D$6:$D$120,0),2)
Name OFcinco: INDEX(Hoja1!$D$6:$E$120,MATCH('Octavos de Final'!$K$23,Hoja1!$D$6:$D$120,0),2)
Name OFcuatro: INDEX(Hoja1!$D$6:$E$120,MATCH('16vos de Final'!$K$19,Hoja1!$D$6:$D$120,0),2)
Name OFcuatro: INDEX(Hoja1!$D$6:$E$120,MATCH('Octavos de Final'!$K$19,Hoja1!$D$6:$D$120,0),2)
Name OFdos: INDEX(Hoja1!$D$6:$E$120,MATCH('16vos de Final'!$K$11,Hoja1!$D$6:$D$120,0),2)
Name OFdos: INDEX(Hoja1!$D$6:$E$120,MATCH('Octavos de Final'!$K$11,Hoja1!$D$6:$D$120,0),2)
Name ofnueve: INDEX(Hoja1!$D$6:$E$120,MATCH('16vos de Final'!$K$39,Hoja1!$D$6:$D$120,0),2)
Name OFocho: INDEX(Hoja1!$D$6:$E$120,MATCH('16vos de Final'!$K$35,Hoja1!$D$6:$D$120,0),2)
Name OFocho: INDEX(Hoja1!$D$6:$E$120,MATCH('Octavos de Final'!$K$35,Hoja1!$D$6:$D$120,0),2)
Name OFseis: INDEX(Hoja1!$D$6:$E$120,MATCH('16vos de Final'!$K$27,Hoja1!$D$6:$D$120,0),2)
Name OFseis: INDEX(Hoja1!$D$6:$E$120,MATCH('Octavos de Final'!$K$27,Hoja1!$D$6:$D$120,0),2)
Name OFsiete: INDEX(Hoja1!$D$6:$E$120,MATCH('16vos de Final'!$K$31,Hoja1!$D$6:$D$120,0),2)
Name OFsiete: INDEX(Hoja1!$D$6:$E$120,MATCH('Octavos de Final'!$K$31,Hoja1!$D$6:$D$120,0),2)
Name OFtres: INDEX(Hoja1!$D$6:$E$120,MATCH('16vos de Final'!$K$15,Hoja1!$D$6:$D$120,0),2)
Name OFtres: INDEX(Hoja1!$D$6:$E$120,MATCH('Octavos de Final'!$K$15,Hoja1!$D$6:$D$120,0),2)
Name OFuno: INDEX(Hoja1!$D$6:$E$120,MATCH('16vos de Final'!$K$7,Hoja1!$D$6:$D$120,0),2)
Name OFuno: INDEX(Hoja1!$D$6:$E$120,MATCH('Octavos de Final'!$K$7,Hoja1!$D$6:$D$120,0),2)
Name SFdos: INDEX(Hoja1!$D$6:$E$120,MATCH(Semifinal!$K$11,Hoja1!$D$6:$D$120,0),2)
Name SFuno: INDEX(Hoja1!$D$6:$E$120,MATCH(Semifinal!$K$7,Hoja1!$D$6:$D$120,0),2)
Name TITULO: INDEX(Hoja1!$G$57:$H$60,MATCH(FINAL!$P$16,Hoja1!$G$57:$G$60,0),2)

Sheet menu
B1: POLLA MUNDIALISTA - 2026 -
C4: Nombre y Apellido: | D4: ROCHO Y MAO | I4: ← Recuerda que si vas a participar con mas de un archivo debes agregar un consecutivo al final Ej: Pedro Perez 1, Pedro Perez 2, etc.
C6: Pais: | D6: COL
F8: ← Digite Pais
C9: Plan de Puntos:
C11: PRIMERA FASE: | D11: Habrá un total de 72 partidos
D12: Por cada RESULTADO acertado (significa adivinar quien gano el partido y/o si quedaron empatados) obtendrá 10 puntos.
D13: Por cada MARCADOR acertado (significa adivinar el marcador independiente de cada Equipo) obtendrá 5 puntos.
D14: Total puntos en juego = 1.440
C16: DIECISEISAVOS: | D16: Clasificaran 32 equipos y habrán 16 encuentros.
D17: Por cada EQUIPO que usted acierte obtendrá 20 puntos. Puntos Posibles = 640
D18: Por cada ENCUENTRO que usted acierte obtendrá 20 puntos. Puntos posibles = 320
D19: Por cada MARCADOR que usted acierte obtendrá 10 puntos. Puntos posibles = 320
D20: Total puntos en juego = 1.280
C22: OCTAVOS: | D22: Clasificaran 16 equipos y habrán 8 encuentros.
D23: Por cada EQUIPO que usted acierte obtendrá 30 puntos. Puntos Posibles = 480
D24: Por cada ENCUENTRO que usted acierte obtendrá 20 puntos. Puntos posibles = 160
D25: Por cada MARCADOR que usted acierte obtendrá 10 puntos. Puntos posibles = 160
D26: Total puntos en juego = 800
C28: CUARTOS: | D28: Clasificaran 8 equipos y habrán 4 encuentros.
D29: Por cada EQUIPO que usted acierte obtendrá 40 puntos. Puntos Posibles = 320
D30: Por cada ENCUENTRO que usted acierte obtendrá 20 puntos. Puntos posibles = 80
D31: Por cada MARCADOR que usted acierte obtendrá 10 puntos. Puntos posibles = 80
D32: Total puntos en juego = 480
C34: SEMI FINAL: | D34: Clasificaran 4 equipos y habrán 2 encuentros.
D35: Por cada EQUIPO que usted acierte obtendrá 50 puntos. Puntos Posibles = 200
D36: Por cada ENCUENTRO que usted acierte obtendrá 20 puntos. Puntos posibles = 40
D37: Por cada MARCADOR que usted acierte obtendrá 10 puntos. Puntos posibles = 40
D38: Total puntos en juego = 280
C40: Partido de 3° Y 4° | D40: 2 equipos y habrá 1 encuentro.
D41: Por cada EQUIPO que usted acierte obtendrá 40 puntos. Puntos Posibles = 80
D42: Si acierta este ENCUENTRO obtendrá 20 puntos.
D43: Por cada MARCADOR que usted acierte obtendrá 10 puntos. Puntos posibles = 20 | K43: TOTAL PUNTOS = 5.000
D44: Total puntos en juego = 120
C46: FINAL: | D46: Clasificaran 2 equipos y habrá 1 encuentro.
D47: Por cada EQUIPO que usted acierte obtendrá 100 puntos. Puntos Posibles = 200
D48: Si acierta este ENCUENTRO obtendrá 20 puntos.
D49: Por cada MARCADOR que usted acierte obtendrá 10 puntos. Puntos posibles = 20
D50: Total puntos en juego = 240
C52: 2° 3° y 4° | D52: si acierta el 2° 100 ptos; si acierta el 3° 40 ptos; si acierta el 4° 20 ptos
...

Sheet - A -
B1: Primera Fase
C4: PROGRAMA DE PARTIDOS | Q4: GRUPO A
H5: Sede | I5: día | K5: hora | M5: obs
B6: =IF(OR(M6="finalizado",M6="en juego",M6="hoy!"),"Ø","") | C6: =IF(R7<>"",R7,"") -> México | D6: 3 | E6: - | F6: 0 | G6: =IF(R9<>"",R9,"") -> Sudáfrica | H6: Ciudad de México | I6: 46184 | K6: 0.58333333 | M6: =IF(OR(I6="",K6="",I6<$R$24),"",IF(I6=$R$24,IF(AND(K6<=$S$26,$S$26<=(K6+0.08333333333)),"en juego",IF($S$26<K6,"hoy!","finalizado")),IF($R$24>I6,"finalizado","")))
B7: =IF(OR(M7="finalizado",M7="en juego",M7="hoy!"),"Ø","") | C7: =IF(R11<>"",R11,"") -> Korea | D7: 0 | E7: - | F7: 2 | G7: =IF(R13<>"",R13,"") -> República Checa | H7: Guadalajara | I7: 46184 | K7: 0.875 | M7: =IF(OR(I7="",K7="",I7<$R$24),"",IF(I7=$R$24,IF(AND(K7<=$S$26,$S$26<=(K7+0.08333333333)),"en juego",IF($S$26<K7,"hoy!","finalizado")),IF($R$24>I7,"finalizado",""))) | R7: México
B8: =IF(OR(M8="finalizado",M8="en juego",M8="hoy!"),"Ø","") | C8: =IF(R13<>"",R13,"") -> República Checa | D8: 2 | E8: - | F8: 1 | G8: =IF(R9<>"",R9,"") -> Sudáfrica | H8: Atlanta | I8: 46191 | K8: 0.45833333 | M8: =IF(OR(I8="",K8="",I8<$R$24),"",IF(I8=$R$24,IF(AND(K8<=$S$26,$S$26<=(K8+0.08333333333)),"en juego",IF($S$26<K8,"hoy!","finalizado")),IF($R$24>I8,"finalizado","")))
B9: =IF(OR(M9="finalizado",M9="en juego",M9="hoy!"),"Ø","") | C9: =IF(R7<>"",R7,"") -> México | D9: 1 | E9: - | F9: 1 | G9: =IF(R11<>"",R11,"") -> Korea | H9: Guadalajara | I9: 46191 | K9: 0.83333333 | M9: =IF(OR(I9="",K9="",I9<$R$24),"",IF(I9=$R$24,IF(AND(K9<=$S$26,$S$26<=(K9+0.08333333333)),"en juego",IF($S$26<K9,"hoy!","finalizado")),IF($R$24>I9,"finalizado",""))) | R9: Sudáfrica
B10: =IF(OR(M10="finalizado",M10="en juego",M10="hoy!"),"Ø","") | C10: =IF(R13<>"",R13,"") -> República Checa | D10: 1 | E10: - | F10: 2 | G10: =IF(R7<>"",R7,"") -> México | H10: Ciudad de México | I10: 46197 | K10: 0.83333333 | M10: =IF(OR(I10="",K10="",I10<$R$24),"",IF(I10=$R$24,IF(AND(K10<=$S$26,$S$26<=(K10+0.08333333333)),"en juego",IF($S$26<K10,"hoy!","finalizado")),IF($R$24>I10,"finalizado","")))
B11: =IF(OR(M11="finalizado",M11="en juego",M11="hoy!"),"Ø","") | C11: =IF(R9<>"",R9,"") -> Sudáfrica | D11: 0 | E11: - | F11: 2 | G11: =IF(R11<>"",R11,"") -> Korea | H11: Monterrey | I11: 46197 | K11: 0.83333333 | M11: =IF(OR(I11="",K11="",I11<$R$24),"",IF(I11=$R$24,IF(AND(K11<=$S$26,$S$26<=(K11+0.08333333333)),"en juego",IF($S$26<K11,"hoy!","finalizado")),IF($R$24>I11,"finalizado",""))) | R11: Korea
C13: =IF(OR(menu!$D$4="",menu!$D$6=""),"Atencion ! Aun te falta poner tu nombre y Pais en la hoja INICIO","") | R13: República Checa
H15: POSICIONES
I16: J | J16: G | K16: E | L16: P | M16: GF | N16: GC | O16: DIF | P16: PTS
G17: Avanza a Dieciseisavos de final Ø | H17: =calculoA!F37 -> México | I17: =calculoA!G37 -> 3 | J17: =calculoA!H37 -> 2 | K17: =calculoA!I37 -> 1 | L17: =calculoA!J37 -> 0 | M17: =calculoA!K37 -> 6 | N17: =calculoA!L37 -> 2 | O17: =M17-N17 -> 4 | P17: =calculoA!M37 -> 7
G18: Avanza a Dieciseisavos de final Ø | H18: =calculoA!F38 -> República Checa | I18: =calculoA!G38 -> 3 | J18: =calculoA!H38 -> 2 | K18: =calculoA!I38 -> 0 | L18: =calculoA!J38 -> 1 | M18: =calculoA!K38 -> 5 | N18: =calculoA!L38 -> 3 | O18: =M18-N18 -> 2 | P18: =calculoA!M38 -> 6
G19: =IF('- 3ros -'!$H$16=144,IF(VLOOKUP(H19,mejores3!$C$21:$T$32,18,0)=1,"Avanza como Mejor tercero: --> ",""),"") -> Avanza como Mejor tercero: --> | H19: =calculoA!F39 -> Korea | I19: =calculoA!G39 -> 3 | J19: =calculoA!H39 -> 1 | K19: =calculoA!I39 -> 1 | L19: =calculoA!J39 -> 1 | M19: =calculoA!K39 -> 3 | N19: =calculoA!L39 -> 3 | O19: =M19-N19 -> 0 | P19: =calculoA!M39 -> 4
H20: =calculoA!F40 -> Sudáfrica | I20: =calculoA!G40 -> 3 | J20: =calculoA!H40 -> 0 | K20: =calculoA!I40 -> 0 | L20: =calculoA!J40 -> 3 | M20: =calculoA!K40 -> 1 | N20: =calculoA!L40 -> 7 | O20: =M20-N20 -> -6 | P20: =calculoA!M40 -> 0
I21: =SUM(I17:I20) -> 12
Q24: fecha y hora actual: | R24: =TODAY() -> 46178 | S24: =NOW() -> 46178.661
R25: =HOUR(S24) -> 15 | S25: =MINUTE(S24) -> 51
S26: =TIME(R25,S25,0) -> 0.66041667

Sheet - B -
B1: Primera Fase
C4: PROGRAMA DE PARTIDOS | Q4: GRUPO B
H5: Sede | I5: día | K5: hora | M5: obs
B6: =IF(OR(M6="finalizado",M6="en juego",M6="hoy!"),"Ø","") | C6: =IF(R7<>"",R7,"") -> Canadá | D6: 2 | E6: - | F6: 0 | G6: =IF(R9<>"",R9,"") -> Bosnia | H6: Toronto | I6: 46185 | K6: 0.58333333 | M6: =IF(OR(I6="",K6="",I6<$R$24),"",IF(I6=$R$24,IF(AND(K6<=$S$26,$S$26<=(K6+0.08333333333)),"en juego",IF($S$26<K6,"hoy!","finalizado")),IF($R$24>I6,"finalizado","")))
B7: =IF(OR(M7="finalizado",M7="en juego",M7="hoy!"),"Ø","") | C7: =IF(R13<>"",R13,"") -> Catar | D7: 0 | E7: - | F7: 3 | G7: =IF(R11<>"",R11,"") -> Suiza | H7: San Francisco | I7: 46186 | K7: 0.58333333 | M7: =IF(OR(I7="",K7="",I7<$R$24),"",IF(I7=$R$24,IF(AND(K7<=$S$26,$S$26<=(K7+0.08333333333)),"en juego",IF($S$26<K7,"hoy!","finalizado")),IF($R$24>I7,"finalizado",""))) | R7: Canadá
B8: =IF(OR(M8="finalizado",M8="en juego",M8="hoy!"),"Ø","") | C8: =IF(R11<>"",R11,"") -> Suiza | D8: 1 | E8: - | F8: 0 | G8: =IF(R9<>"",R9,"") -> Bosnia | H8: Los Ángeles | I8: 46191 | K8: 0.58333333 | M8: =IF(OR(I8="",K8="",I8<$R$24),"",IF(I8=$R$24,IF(AND(K8<=$S$26,$S$26<=(K8+0.08333333333)),"en juego",IF($S$26<K8,"hoy!","finalizado")),IF($R$24>I8,"finalizado","")))
B9: =IF(OR(M9="finalizado",M9="en juego",M9="hoy!"),"Ø","") | C9: =IF(R7<>"",R7,"") -> Canadá | D9: 1 | E9: - | F9: 1 | G9: =IF(R13<>"",R13,"") -> Catar | H9: Vancouver | I9: 46191 | K9: 0.70833333 | M9: =IF(OR(I9="",K9="",I9<$R$24),"",IF(I9=$R$24,IF(AND(K9<=$S$26,$S$26<=(K9+0.08333333333)),"en juego",IF($S$26<K9,"hoy!","finalizado")),IF($R$24>I9,"finalizado",""))) | R9: Bosnia
B10: =IF(OR(M10="finalizado",M10="en juego",M10="hoy!"),"Ø","") | C10: =IF(R11<>"",R11,"") -> Suiza | D10: 1 | E10: - | F10: 1 | G10: =IF(R7<>"",R7,"") -> Canadá | H10: Vancouver | I10: 46197 | K10: 0.58333333 | M10: =IF(OR(I10="",K10="",I10<$R$24),"",IF(I10=$R$24,IF(AND(K10<=$S$26,$S$26<=(K10+0.08333333333)),"en juego",IF($S$26<K10,"hoy!","finalizado")),IF($R$24>I10,"finalizado","")))
B11: =IF(OR(M11="finalizado",M11="en juego",M11="hoy!"),"Ø","") | C11: =IF(R9<>"",R9,"") -> Bosnia | D11: 3 | E11: - | F11: 1 | G11: =IF(R13<>"",R13,"") -> Catar | H11: Seattle | I11: 46197 | K11: 0.58333333 | M11: =IF(OR(I11="",K11="",I11<$R$24),"",IF(I11=$R$24,IF(AND(K11<=$S$26,$S$26<=(K11+0.08333333333)),"en juego",IF($S$26<K11,"hoy!","finalizado")),IF($R$24>I11,"finalizado",""))) | R11: Suiza
C13: =IF(OR(menu!$D$4="",menu!$D$6=""),"Atencion ! Aun te falta poner tu nombre y Pais en la hoja INICIO","") | R13: Catar
H15: POSICIONES
I16: J | J16: G | K16: E | L16: P | M16: GF | N16: GC | O16: DIF | P16: PTS
G17: Avanza a Dieciseisavos de final Ø | H17: =calculoB!F37 -> Suiza | I17: =calculoB!G37 -> 3 | J17: =calculoB!H37 -> 2 | K17: =calculoB!I37 -> 1 | L17: =calculoB!J37 -> 0 | M17: =calculoB!K37 -> 5 | N17: =calculoB!L37 -> 1 | O17: =M17-N17 -> 4 | P17: =calculoB!M37 -> 7
G18: Avanza a Dieciseisavos de final Ø | H18: =calculoB!F38 -> Canadá | I18: =calculoB!G38 -> 3 | J18: =calculoB!H38 -> 1 | K18: =calculoB!I38 -> 2 | L18: =calculoB!J38 -> 0 | M18: =calculoB!K38 -> 4 | N18: =calculoB!L38 -> 2 | O18: =M18-N18 -> 2 | P18: =calculoB!M38 -> 5
G19: =IF('- 3ros -'!$H$16=144,IF(VLOOKUP(H19,mejores3!$C$21:$T$32,18,0)=1,"Avanza como Mejor tercero: --> ",""),"") -> Avanza como Mejor tercero: --> | H19: =calculoB!F39 -> Bosnia | I19: =calculoB!G39 -> 3 | J19: =calculoB!H39 -> 1 | K19: =calculoB!I39 -> 0 | L19: =calculoB!J39 -> 2 | M19: =calculoB!K39 -> 3 | N19: =calculoB!L39 -> 4 | O19: =M19-N19 -> -1 | P19: =calculoB!M39 -> 3
H20: =calculoB!F40 -> Catar | I20: =calculoB!G40 -> 3 | J20: =calculoB!H40 -> 0 | K20: =calculoB!I40 -> 1 | L20: =calculoB!J40 -> 2 | M20: =calculoB!K40 -> 2 | N20: =calculoB!L40 -> 7 | O20: =M20-N20 -> -5 | P20: =calculoB!M40 -> 1
I21: =SUM(I17:I20) -> 12
Q24: fecha y hora actual: | R24: =TODAY() -> 46178 | S24: =NOW() -> 46178.661
R25: =HOUR(S24) -> 15 | S25: =MINUTE(S24) -> 51
S26: =TIME(R25,S25,0) -> 0.66041667

Sheet - C -
B1: Primera Fase
C4: PROGRAMA DE PARTIDOS | Q4: GRUPO C
H5: Sede | I5: día | K5: hora | M5: obs
B6: =IF(OR(M6="finalizado",M6="en juego",M6="hoy!"),"Ø","") | C6: =IF(R7<>"",R7,"") -> Brasil | D6: 2 | E6: - | F6: 1 | G6: =IF(R9<>"",R9,"") -> Marruecos | H6: Nueva York | I6: 46186 | K6: 0.70833333 | M6: =IF(OR(I6="",K6="",I6<$R$24),"",IF(I6=$R$24,IF(AND(K6<=$S$26,$S$26<=(K6+0.08333333333)),"en juego",IF($S$26<K6,"hoy!","finalizado")),IF($R$24>I6,"finalizado","")))
B7: =IF(OR(M7="finalizado",M7="en juego",M7="hoy!"),"Ø","") | C7: =IF(R11<>"",R11,"") -> Haití | D7: 0 | E7: - | F7: 3 | G7: =IF(R13<>"",R13,"") -> Escocia | H7: Boston | I7: 46186 | K7: 0.83333333 | M7: =IF(OR(I7="",K7="",I7<$R$24),"",IF(I7=$R$24,IF(AND(K7<=$S$26,$S$26<=(K7+0.08333333333)),"en juego",IF($S$26<K7,"hoy!","finalizado")),IF($R$24>I7,"finalizado",""))) | R7: Brasil
B8: =IF(OR(M8="finalizado",M8="en juego",M8="hoy!"),"Ø","") | C8: =IF(R13<>"",R13,"") -> Escocia | D8: 0 | E8: - | F8: 0 | G8: =IF(R9<>"",R9,"") -> Marruecos | H8: Boston | I8: 46192 | K8: 0.70833333 | M8: =IF(OR(I8="",K8="",I8<$R$24),"",IF(I8=$R$24,IF(AND(K8<=$S$26,$S$26<=(K8+0.08333333333)),"en juego",IF($S$26<K8,"hoy!","finalizado")),IF($R$24>I8,"finalizado","")))
B9: =IF(OR(M9="finalizado",M9="en juego",M9="hoy!"),"Ø","") | C9: =IF(R7<>"",R7,"") -> Brasil | D9: 3 | E9: - | F9: 0 | G9: =IF(R11<>"",R11,"") -> Haití | H9: Filadelfia | I9: 46192 | K9: 0.8125 | M9: =IF(OR(I9="",K9="",I9<$R$24),"",IF(I9=$R$24,IF(AND(K9<=$S$26,$S$26<=(K9+0.08333333333)),"en juego",IF($S$26<K9,"hoy!","finalizado")),IF($R$24>I9,"finalizado",""))) | R9: Marruecos
B10: =IF(OR(M10="finalizado",M10="en juego",M10="hoy!"),"Ø","") | C10: =IF(R13<>"",R13,"") -> Escocia | D10: 2 | E10: - | F10: 2 | G10: =IF(R7<>"",R7,"") -> Brasil | H10: Miami | I10: 46197 | K10: 0.70833333 | M10: =IF(OR(I10="",K10="",I10<$R$24),"",IF(I10=$R$24,IF(AND(K10<=$S$26,$S$26<=(K10+0.08333333333)),"en juego",IF($S$26<K10,"hoy!","finalizado")),IF($R$24>I10,"finalizado","")))
B11: =IF(OR(M11="finalizado",M11="en juego",M11="hoy!"),"Ø","") | C11: =IF(R9<>"",R9,"") -> Marruecos | D11: 1 | E11: - | F11: 0 | G11: =IF(R11<>"",R11,"") -> Haití | H11: Atlanta | I11: 46197 | K11: 0.70833333 | M11: =IF(OR(I11="",K11="",I11<$R$24),"",IF(I11=$R$24,IF(AND(K11<=$S$26,$S$26<=(K11+0.08333333333)),"en juego",IF($S$26<K11,"hoy!","finalizado")),IF($R$24>I11,"finalizado",""))) | R11: Haití
C13: =IF(OR(menu!$D$4="",menu!$D$6=""),"Atencion ! Aun te falta poner tu nombre y Pais en la hoja INICIO","") | R13: Escocia
H15: POSICIONES
I16: J | J16: G | K16: E | L16: P | M16: GF | N16: GC | O16: DIF | P16: PTS
G17: Avanza a Dieciseisavos de final Ø | H17: =calculoC!F37 -> Brasil | I17: =calculoC!G37 -> 3 | J17: =calculoC!H37 -> 2 | K17: =calculoC!I37 -> 1 | L17: =calculoC!J37 -> 0 | M17: =calculoC!K37 -> 7 | N17: =calculoC!L37 -> 3 | O17: =M17-N17 -> 4 | P17: =calculoC!M37 -> 7
G18: Avanza a Dieciseisavos de final Ø | H18: =calculoC!F38 -> Escocia | I18: =calculoC!G38 -> 3 | J18: =calculoC!H38 -> 1 | K18: =calculoC!I38 -> 2 | L18: =calculoC!J38 -> 0 | M18: =calculoC!K38 -> 5 | N18: =calculoC!L38 -> 2 | O18: =M18-N18 -> 3 | P18: =calculoC!M38 -> 5
G19: =IF('- 3ros -'!$H$16=144,IF(VLOOKUP(H19,mejores3!$C$21:$T$32,18,0)=1,"Avanza como Mejor tercero: --> ",""),"") -> Avanza como Mejor tercero: --> | H19: =calculoC!F39 -> Marruecos | I19: =calculoC!G39 -> 3 | J19: =calculoC!H39 -> 1 | K19: =calculoC!I39 -> 1 | L19: =calculoC!J39 -> 1 | M19: =calculoC!K39 -> 2 | N19: =calculoC!L39 -> 2 | O19: =M19-N19 -> 0 | P19: =calculoC!M39 -> 4
H20: =calculoC!F40 -> Haití | I20: =calculoC!G40 -> 3 | J20: =calculoC!H40 -> 0 | K20: =calculoC!I40 -> 0 | L20: =calculoC!J40 -> 3 | M20: =calculoC!K40 -> 0 | N20: =calculoC!L40 -> 7 | O20: =M20-N20 -> -7 | P20: =calculoC!M40 -> 0
I21: =SUM(I17:I20) -> 12
Q24: fecha y hora actual: | R24: =TODAY() -> 46178 | S24: =NOW() -> 46178.661
R25: =HOUR(S24) -> 15 | S25: =MINUTE(S24) -> 51
S26: =TIME(R25,S25,0) -> 0.66041667

Sheet - D -
B1: Primera Fase
C4: PROGRAMA DE PARTIDOS | Q4: GRUPO D
H5: Sede | I5: día | K5: hora | M5: obs
B6: =IF(OR(M6="finalizado",M6="en juego",M6="hoy!"),"Ø","") | C6: =IF(R7<>"",R7,"") -> EE. UU. | D6: 1 | E6: - | F6: 0 | G6: =IF(R9<>"",R9,"") -> Paraguay | H6: Los Ángeles | I6: 46185 | K6: 0.83333333 | M6: =IF(OR(I6="",K6="",I6<$R$24),"",IF(I6=$R$24,IF(AND(K6<=$S$26,$S$26<=(K6+0.08333333333)),"en juego",IF($S$26<K6,"hoy!","finalizado")),IF($R$24>I6,"finalizado","")))
B7: =IF(OR(M7="finalizado",M7="en juego",M7="hoy!"),"Ø","") | C7: =IF(R11<>"",R11,"") -> Australia | D7: 1 | E7: - | F7: 2 | G7: =IF(R13<>"",R13,"") -> Turquía | H7: Vancouver | I7: 46186 | K7: 0.95833333 | M7: =IF(OR(I7="",K7="",I7<$R$24),"",IF(I7=$R$24,IF(AND(K7<=$S$26,$S$26<=(K7+0.08333333333)),"en juego",IF($S$26<K7,"hoy!","finalizado")),IF($R$24>I7,"finalizado",""))) | R7: EE. UU.
B8: =IF(OR(M8="finalizado",M8="en juego",M8="hoy!"),"Ø","") | C8: =IF(R7<>"",R7,"") -> EE. UU. | D8: 2 | E8: - | F8: 1 | G8: =IF(R11<>"",R11,"") -> Australia | H8: Seattle | I8: 46192 | K8: 0.58333333 | M8: =IF(OR(I8="",K8="",I8<$R$24),"",IF(I8=$R$24,IF(AND(K8<=$S$26,$S$26<=(K8+0.08333333333)),"en juego",IF($S$26<K8,"hoy!","finalizado")),IF($R$24>I8,"finalizado","")))
B9: =IF(OR(M9="finalizado",M9="en juego",M9="hoy!"),"Ø","") | C9: =IF(R13<>"",R13,"") -> Turquía | D9: 1 | E9: - | F9: 0 | G9: =IF(R9<>"",R9,"") -> Paraguay | H9: San Francisco | I9: 46192 | K9: 0.91666667 | M9: =IF(OR(I9="",K9="",I9<$R$24),"",IF(I9=$R$24,IF(AND(K9<=$S$26,$S$26<=(K9+0.08333333333)),"en juego",IF($S$26<K9,"hoy!","finalizado")),IF($R$24>I9,"finalizado",""))) | R9: Paraguay
B10: =IF(OR(M10="finalizado",M10="en juego",M10="hoy!"),"Ø","") | C10: =IF(R13<>"",R13,"") -> Turquía | D10: 0 | E10: - | F10: 0 | G10: =IF(R7<>"",R7,"") -> EE. UU. | H10: Los Ángeles | I10: 46198 | K10: 0.875 | M10: =IF(OR(I10="",K10="",I10<$R$24),"",IF(I10=$R$24,IF(AND(K10<=$S$26,$S$26<=(K10+0.08333333333)),"en juego",IF($S$26<K10,"hoy!","finalizado")),IF($R$24>I10,"finalizado","")))
B11: =IF(OR(M11="finalizado",M11="en juego",M11="hoy!"),"Ø","") | C11: =IF(R9<>"",R9,"") -> Paraguay | D11: 2 | E11: - | F11: 0 | G11: =IF(R11<>"",R11,"") -> Australia | H11: San Francisco | I11: 46198 | K11: 0.875 | M11: =IF(OR(I11="",K11="",I11<$R$24),"",IF(I11=$R$24,IF(AND(K11<=$S$26,$S$26<=(K11+0.08333333333)),"en juego",IF($S$26<K11,"hoy!","finalizado")),IF($R$24>I11,"finalizado",""))) | R11: Australia
C13: =IF(OR(menu!$D$4="",menu!$D$6=""),"Atencion ! Aun te falta poner tu nombre y Pais en la hoja INICIO","") | R13: Turquía
H15: POSICIONES
I16: J | J16: G | K16: E | L16: P | M16: GF | N16: GC | O16: DIF | P16: PTS
G17: Avanza a Dieciseisavos de final Ø | H17: =calculoD!F37 -> EE. UU. | I17: =calculoD!G37 -> 3 | J17: =calculoD!H37 -> 2 | K17: =calculoD!I37 -> 1 | L17: =calculoD!J37 -> 0 | M17: =calculoD!K37 -> 3 | N17: =calculoD!L37 -> 1 | O17: =M17-N17 -> 2 | P17: =calculoD!M37 -> 7
G18: Avanza a Dieciseisavos de final Ø | H18: =calculoD!F38 -> Turquía | I18: =calculoD!G38 -> 3 | J18: =calculoD!H38 -> 2 | K18: =calculoD!I38 -> 1 | L18: =calculoD!J38 -> 0 | M18: =calculoD!K38 -> 3 | N18: =calculoD!L38 -> 1 | O18: =M18-N18 -> 2 | P18: =calculoD!M38 -> 7
G19: =IF('- 3ros -'!$H$16=144,IF(VLOOKUP(H19,mejores3!$C$21:$T$32,18,0)=1,"Avanza como Mejor tercero: --> ",""),"") -> Avanza como Mejor tercero: --> | H19: =calculoD!F39 -> Paraguay | I19: =calculoD!G39 -> 3 | J19: =calculoD!H39 -> 1 | K19: =calculoD!I39 -> 0 | L19: =calculoD!J39 -> 2 | M19: =calculoD!K39 -> 2 | N19: =calculoD!L39 -> 2 | O19: =M19-N19 -> 0 | P19: =calculoD!M39 -> 3
H20: =calculoD!F40 -> Australia | I20: =calculoD!G40 -> 3 | J20: =calculoD!H40 -> 0 | K20: =calculoD!I40 -> 0 | L20: =calculoD!J40 -> 3 | M20: =calculoD!K40 -> 2 | N20: =calculoD!L40 -> 6 | O20: =M20-N20 -> -4 | P20: =calculoD!M40 -> 0
I21: =SUM(I17:I20) -> 12
Q24: fecha y hora actual: | R24: =TODAY() -> 46178 | S24: =NOW() -> 46178.661
R25: =HOUR(S24) -> 15 | S25: =MINUTE(S24) -> 51
S26: =TIME(R25,S25,0) -> 0.66041667

Sheet - E -
B1: Primera Fase
C4: PROGRAMA DE PARTIDOS | Q4: GRUPO E
H5: Sede | I5: día | K5: hora | M5: obs
B6: =IF(OR(M6="finalizado",M6="en juego",M6="hoy!"),"Ø","") | C6: =IF(R7<>"",R7,"") -> Alemania | D6: 4 | E6: - | F6: 0 | G6: =IF(R9<>"",R9,"") -> Curazao | H6: Houston | I6: 46187 | K6: 0.5 | M6: =IF(OR(I6="",K6="",I6<$R$24),"",IF(I6=$R$24,IF(AND(K6<=$S$26,$S$26<=(K6+0.08333333333)),"en juego",IF($S$26<K6,"hoy!","finalizado")),IF($R$24>I6,"finalizado","")))
B7: =IF(OR(M7="finalizado",M7="en juego",M7="hoy!"),"Ø","") | C7: =IF(R11<>"",R11,"") -> Costa de Marfil | D7: 1 | E7: - | F7: 1 | G7: =IF(R13<>"",R13,"") -> Ecuador | H7: Filadelfia | I7: 46187 | K7: 0.75 | M7: =IF(OR(I7="",K7="",I7<$R$24),"",IF(I7=$R$24,IF(AND(K7<=$S$26,$S$26<=(K7+0.08333333333)),"en juego",IF($S$26<K7,"hoy!","finalizado")),IF($R$24>I7,"finalizado",""))) | R7: Alemania
B8: =IF(OR(M8="finalizado",M8="en juego",M8="hoy!"),"Ø","") | C8: =IF(R7<>"",R7,"") -> Alemania | D8: 3 | E8: - | F8: 0 | G8: =IF(R11<>"",R11,"") -> Costa de Marfil | H8: Toronto | I8: 46193 | K8: 0.625 | M8: =IF(OR(I8="",K8="",I8<$R$24),"",IF(I8=$R$24,IF(AND(K8<=$S$26,$S$26<=(K8+0.08333333333)),"en juego",IF($S$26<K8,"hoy!","finalizado")),IF($R$24>I8,"finalizado","")))
B9: =IF(OR(M9="finalizado",M9="en juego",M9="hoy!"),"Ø","") | C9: =IF(R13<>"",R13,"") -> Ecuador | D9: 2 | E9: - | F9: 0 | G9: =IF(R9<>"",R9,"") -> Curazao | H9: Kansas City | I9: 46193 | K9: 0.79166667 | M9: =IF(OR(I9="",K9="",I9<$R$24),"",IF(I9=$R$24,IF(AND(K9<=$S$26,$S$26<=(K9+0.08333333333)),"en juego",IF($S$26<K9,"hoy!","finalizado")),IF($R$24>I9,"finalizado",""))) | R9: Curazao
B10: =IF(OR(M10="finalizado",M10="en juego",M10="hoy!"),"Ø","") | C10: =IF(R9<>"",R9,"") -> Curazao | D10: 1 | E10: - | F10: 2 | G10: =IF(R11<>"",R11,"") -> Costa de Marfil | H10: Filadelfia | I10: 46198 | K10: 0.625 | M10: =IF(OR(I10="",K10="",I10<$R$24),"",IF(I10=$R$24,IF(AND(K10<=$S$26,$S$26<=(K10+0.08333333333)),"en juego",IF($S$26<K10,"hoy!","finalizado")),IF($R$24>I10,"finalizado","")))
B11: =IF(OR(M11="finalizado",M11="en juego",M11="hoy!"),"Ø","") | C11: =IF(R13<>"",R13,"") -> Ecuador | D11: 0 | E11: - | F11: 2 | G11: =IF(R7<>"",R7,"") -> Alemania | H11: Nueva York | I11: 46198 | K11: 0.625 | M11: =IF(OR(I11="",K11="",I11<$R$24),"",IF(I11=$R$24,IF(AND(K11<=$S$26,$S$26<=(K11+0.08333333333)),"en juego",IF($S$26<K11,"hoy!","finalizado")),IF($R$24>I11,"finalizado",""))) | R11: Costa de Marfil
C13: =IF(OR(menu!$D$4="",menu!$D$6=""),"Atencion ! Aun te falta poner tu nombre y Pais en la hoja INICIO","") | R13: Ecuador
H15: POSICIONES
I16: J | J16: G | K16: E | L16: P | M16: GF | N16: GC | O16: DIF | P16: PTS
G17: Avanza a Dieciseisavos de final Ø | H17: =calculoE!F37 -> Alemania | I17: =calculoE!G37 -> 3 | J17: =calculoE!H37 -> 3 | K17: =calculoE!I37 -> 0 | L17: =calculoE!J37 -> 0 | M17: =calculoE!K37 -> 9 | N17: =calculoE!L37 -> 0 | O17: =M17-N17 -> 9 | P17: =calculoE!M37 -> 9
G18: Avanza a Dieciseisavos de final Ø | H18: =calculoE!F38 -> Ecuador | I18: =calculoE!G38 -> 3 | J18: =calculoE!H38 -> 1 | K18: =calculoE!I38 -> 1 | L18: =calculoE!J38 -> 1 | M18: =calculoE!K38 -> 3 | N18: =calculoE!L38 -> 3 | O18: =M18-N18 -> 0 | P18: =calculoE!M38 -> 4
G19: =IF('- 3ros -'!$H$16=144,IF(VLOOKUP(H19,mejores3!$C$21:$T$32,18,0)=1,"Avanza como Mejor tercero: --> ",""),"") -> Avanza como Mejor tercero: --> | H19: =calculoE!F39 -> Costa de Marfil | I19: =calculoE!G39 -> 3 | J19: =calculoE!H39 -> 1 | K19: =calculoE!I39 -> 1 | L19: =calculoE!J39 -> 1 | M19: =calculoE!K39 -> 3 | N19: =calculoE!L39 -> 5 | O19: =M19-N19 -> -2 | P19: =calculoE!M39 -> 4
H20: =calculoE!F40 -> Curazao | I20: =calculoE!G40 -> 3 | J20: =calculoE!H40 -> 0 | K20: =calculoE!I40 -> 0 | L20: =calculoE!J40 -> 3 | M20: =calculoE!K40 -> 1 | N20: =calculoE!L40 -> 8 | O20: =M20-N20 -> -7 | P20: =calculoE!M40 -> 0
I21: =SUM(I17:I20) -> 12
Q24: fecha y hora actual: | R24: =TODAY() -> 46178 | S24: =NOW() -> 46178.661
R25: =HOUR(S24) -> 15 | S25: =MINUTE(S24) -> 51
S26: =TIME(R25,S25,0) -> 0.66041667

Sheet - F -
B1: Primera Fase
C4: PROGRAMA DE PARTIDOS | Q4: GRUPO F
H5: Sede | I5: día | K5: hora | M5: obs
B6: =IF(OR(M6="finalizado",M6="en juego",M6="hoy!"),"Ø","") | C6: =IF(R7<>"",R7,"") -> Países Bajos | D6: 1 | E6: - | F6: 1 | G6: =IF(R9<>"",R9,"") -> Japón | H6: Dallas | I6: 46187 | K6: 0.625 | M6: =IF(OR(I6="",K6="",I6<$R$24),"",IF(I6=$R$24,IF(AND(K6<=$S$26,$S$26<=(K6+0.08333333333)),"en juego",IF($S$26<K6,"hoy!","finalizado")),IF($R$24>I6,"finalizado","")))
B7: =IF(OR(M7="finalizado",M7="en juego",M7="hoy!"),"Ø","") | C7: =IF(R11<>"",R11,"") -> Suecia | D7: 2 | E7: - | F7: 0 | G7: =IF(R13<>"",R13,"") -> Túnez | H7: Monterrey | I7: 46187 | K7: 0.875 | M7: =IF(OR(I7="",K7="",I7<$R$24),"",IF(I7=$R$24,IF(AND(K7<=$S$26,$S$26<=(K7+0.08333333333)),"en juego",IF($S$26<K7,"hoy!","finalizado")),IF($R$24>I7,"finalizado",""))) | R7: Países Bajos
B8: =IF(OR(M8="finalizado",M8="en juego",M8="hoy!"),"Ø","") | C8: =IF(R7<>"",R7,"") -> Países Bajos | D8: 2 | E8: - | F8: 1 | G8: =IF(R11<>"",R11,"") -> Suecia | H8: Houston | I8: 46193 | K8: 0.5 | M8: =IF(OR(I8="",K8="",I8<$R$24),"",IF(I8=$R$24,IF(AND(K8<=$S$26,$S$26<=(K8+0.08333333333)),"en juego",IF($S$26<K8,"hoy!","finalizado")),IF($R$24>I8,"finalizado","")))
B9: =IF(OR(M9="finalizado",M9="en juego",M9="hoy!"),"Ø","") | C9: =IF(R13<>"",R13,"") -> Túnez | D9: 0 | E9: - | F9: 0 | G9: =IF(R9<>"",R9,"") -> Japón | H9: Monterrey | I9: 46193 | K9: 0.95833333 | M9: =IF(OR(I9="",K9="",I9<$R$24),"",IF(I9=$R$24,IF(AND(K9<=$S$26,$S$26<=(K9+0.08333333333)),"en juego",IF($S$26<K9,"hoy!","finalizado")),IF($R$24>I9,"finalizado",""))) | R9: Japón
B10: =IF(OR(M10="finalizado",M10="en juego",M10="hoy!"),"Ø","") | C10: =IF(R9<>"",R9,"") -> Japón | D10: 2 | E10: - | F10: 0 | G10: =IF(R11<>"",R11,"") -> Suecia | H10: Dallas | I10: 46198 | K10: 0.75 | M10: =IF(OR(I10="",K10="",I10<$R$24),"",IF(I10=$R$24,IF(AND(K10<=$S$26,$S$26<=(K10+0.08333333333)),"en juego",IF($S$26<K10,"hoy!","finalizado")),IF($R$24>I10,"finalizado","")))
B11: =IF(OR(M11="finalizado",M11="en juego",M11="hoy!"),"Ø","") | C11: =IF(R13<>"",R13,"") -> Túnez | D11: 0 | E11: - | F11: 3 | G11: =IF(R7<>"",R7,"") -> Países Bajos | H11: Kansas City | I11: 46198 | K11: 0.75 | M11: =IF(OR(I11="",K11="",I11<$R$24),"",IF(I11=$R$24,IF(AND(K11<=$S$26,$S$26<=(K11+0.08333333333)),"en juego",IF($S$26<K11,"hoy!","finalizado")),IF($R$24>I11,"finalizado",""))) | R11: Suecia
C13: =IF(OR(menu!$D$4="",menu!$D$6=""),"Atencion ! Aun te falta poner tu nombre y Pais en la hoja INICIO","") | R13: Túnez
H15: POSICIONES
I16: J | J16: G | K16: E | L16: P | M16: GF | N16: GC | O16: DIF | P16: PTS
G17: Avanza a Dieciseisavos de final Ø | H17: =calculoF!F37 -> Países Bajos | I17: =calculoF!G37 -> 3 | J17: =calculoF!H37 -> 2 | K17: =calculoF!I37 -> 1 | L17: =calculoF!J37 -> 0 | M17: =calculoF!K37 -> 6 | N17: =calculoF!L37 -> 2 | O17: =M17-N17 -> 4 | P17: =calculoF!M37 -> 7
G18: Avanza a Dieciseisavos de final Ø | H18: =calculoF!F38 -> Japón | I18: =calculoF!G38 -> 3 | J18: =calculoF!H38 -> 1 | K18: =calculoF!I38 -> 2 | L18: =calculoF!J38 -> 0 | M18: =calculoF!K38 -> 3 | N18: =calculoF!L38 -> 1 | O18: =M18-N18 -> 2 | P18: =calculoF!M38 -> 5
G19: =IF('- 3ros -'!$H$16=144,IF(VLOOKUP(H19,mejores3!$C$21:$T$32,18,0)=1,"Avanza como Mejor tercero: --> ",""),"") -> Avanza como Mejor tercero: --> | H19: =calculoF!F39 -> Suecia | I19: =calculoF!G39 -> 3 | J19: =calculoF!H39 -> 1 | K19: =calculoF!I39 -> 0 | L19: =calculoF!J39 -> 2 | M19: =calculoF!K39 -> 3 | N19: =calculoF!L39 -> 4 | O19: =M19-N19 -> -1 | P19: =calculoF!M39 -> 3
H20: =calculoF!F40 -> Túnez | I20: =calculoF!G40 -> 3 | J20: =calculoF!H40 -> 0 | K20: =calculoF!I40 -> 1 | L20: =calculoF!J40 -> 2 | M20: =calculoF!K40 -> 0 | N20: =calculoF!L40 -> 5 | O20: =M20-N20 -> -5 | P20: =calculoF!M40 -> 1
I21: =SUM(I17:I20) -> 12
Q24: fecha y hora actual: | R24: =TODAY() -> 46178 | S24: =NOW() -> 46178.661
R25: =HOUR(S24) -> 15 | S25: =MINUTE(S24) -> 51
S26: =TIME(R25,S25,0) -> 0.66041667

Sheet - G -
B1: Primera Fase
C4: PROGRAMA DE PARTIDOS | Q4: GRUPO G
H5: Sede | I5: día | K5: hora | M5: obs
B6: =IF(OR(M6="finalizado",M6="en juego",M6="hoy!"),"Ø","") | C6: =IF(R7<>"",R7,"") -> Bélgica | D6: 2 | E6: - | F6: 0 | G6: =IF(R9<>"",R9,"") -> Egipto | H6: Seattle | I6: 46188 | K6: 0.58333333 | M6: =IF(OR(I6="",K6="",I6<$R$24),"",IF(I6=$R$24,IF(AND(K6<=$S$26,$S$26<=(K6+0.08333333333)),"en juego",IF($S$26<K6,"hoy!","finalizado")),IF($R$24>I6,"finalizado","")))
B7: =IF(OR(M7="finalizado",M7="en juego",M7="hoy!"),"Ø","") | C7: =IF(R11<>"",R11,"") -> Irán | D7: 1 | E7: - | F7: 0 | G7: =IF(R13<>"",R13,"") -> Nueva Zelanda | H7: Los Ángeles | I7: 46188 | K7: 0.83333333 | M7: =IF(OR(I7="",K7="",I7<$R$24),"",IF(I7=$R$24,IF(AND(K7<=$S$26,$S$26<=(K7+0.08333333333)),"en juego",IF($S$26<K7,"hoy!","finalizado")),IF($R$24>I7,"finalizado",""))) | R7: Bélgica
B8: =IF(OR(M8="finalizado",M8="en juego",M8="hoy!"),"Ø","") | C8: =IF(R7<>"",R7,"") -> Bélgica | D8: 1 | E8: - | F8: 0 | G8: =IF(R11<>"",R11,"") -> Irán | H8: Los Ángeles | I8: 46194 | K8: 0.58333333 | M8: =IF(OR(I8="",K8="",I8<$R$24),"",IF(I8=$R$24,IF(AND(K8<=$S$26,$S$26<=(K8+0.08333333333)),"en juego",IF($S$26<K8,"hoy!","finalizado")),IF($R$24>I8,"finalizado","")))
B9: =IF(OR(M9="finalizado",M9="en juego",M9="hoy!"),"Ø","") | C9: =IF(R13<>"",R13,"") -> Nueva Zelanda | D9: 0 | E9: - | F9: 3 | G9: =IF(R9<>"",R9,"") -> Egipto | H9: Vancouver | I9: 46194 | K9: 0.83333333 | M9: =IF(OR(I9="",K9="",I9<$R$24),"",IF(I9=$R$24,IF(AND(K9<=$S$26,$S$26<=(K9+0.08333333333)),"en juego",IF($S$26<K9,"hoy!","finalizado")),IF($R$24>I9,"finalizado",""))) | R9: Egipto
B10: =IF(OR(M10="finalizado",M10="en juego",M10="hoy!"),"Ø","") | C10: =IF(R9<>"",R9,"") -> Egipto | D10: 1 | E10: - | F10: 1 | G10: =IF(R11<>"",R11,"") -> Irán | H10: Seattle | I10: 46199 | K10: 0.91666667 | M10: =IF(OR(I10="",K10="",I10<$R$24),"",IF(I10=$R$24,IF(AND(K10<=$S$26,$S$26<=(K10+0.08333333333)),"en juego",IF($S$26<K10,"hoy!","finalizado")),IF($R$24>I10,"finalizado","")))
B11: =IF(OR(M11="finalizado",M11="en juego",M11="hoy!"),"Ø","") | C11: =IF(R13<>"",R13,"") -> Nueva Zelanda | D11: 1 | E11: - | F11: 1 | G11: =IF(R7<>"",R7,"") -> Bélgica | H11: Vancouver | I11: 46199 | K11: 0.91666667 | M11: =IF(OR(I11="",K11="",I11<$R$24),"",IF(I11=$R$24,IF(AND(K11<=$S$26,$S$26<=(K11+0.08333333333)),"en juego",IF($S$26<K11,"hoy!","finalizado")),IF($R$24>I11,"finalizado",""))) | R11: Irán
C13: =IF(OR(menu!$D$4="",menu!$D$6=""),"Atencion ! Aun te falta poner tu nombre y Pais en la hoja INICIO","") | R13: Nueva Zelanda
H15: POSICIONES
I16: J | J16: G | K16: E | L16: P | M16: GF | N16: GC | O16: DIF | P16: PTS
G17: Avanza a Dieciseisavos de final Ø | H17: =calculoG!F37 -> Bélgica | I17: =calculoG!G37 -> 3 | J17: =calculoG!H37 -> 2 | K17: =calculoG!I37 -> 1 | L17: =calculoG!J37 -> 0 | M17: =calculoG!K37 -> 4 | N17: =calculoG!L37 -> 1 | O17: =M17-N17 -> 3 | P17: =calculoG!M37 -> 7
G18: Avanza a Dieciseisavos de final Ø | H18: =calculoG!F38 -> Egipto | I18: =calculoG!G38 -> 3 | J18: =calculoG!H38 -> 1 | K18: =calculoG!I38 -> 1 | L18: =calculoG!J38 -> 1 | M18: =calculoG!K38 -> 4 | N18: =calculoG!L38 -> 3 | O18: =M18-N18 -> 1 | P18: =calculoG!M38 -> 4
G19: =IF('- 3ros -'!$H$16=144,IF(VLOOKUP(H19,mejores3!$C$21:$T$32,18,0)=1,"Avanza como Mejor tercero: --> ",""),"") -> Avanza como Mejor tercero: --> | H19: =calculoG!F39 -> Irán | I19: =calculoG!G39 -> 3 | J19: =calculoG!H39 -> 1 | K19: =calculoG!I39 -> 1 | L19: =calculoG!J39 -> 1 | M19: =calculoG!K39 -> 2 | N19: =calculoG!L39 -> 2 | O19: =M19-N19 -> 0 | P19: =calculoG!M39 -> 4
H20: =calculoG!F40 -> Nueva Zelanda | I20: =calculoG!G40 -> 3 | J20: =calculoG!H40 -> 0 | K20: =calculoG!I40 -> 1 | L20: =calculoG!J40 -> 2 | M20: =calculoG!K40 -> 1 | N20: =calculoG!L40 -> 5 | O20: =M20-N20 -> -4 | P20: =calculoG!M40 -> 1
I21: =SUM(I17:I20) -> 12
Q24: fecha y hora actual: | R24: =TODAY() -> 46178 | S24: =NOW() -> 46178.661
R25: =HOUR(S24) -> 15 | S25: =MINUTE(S24) -> 51
S26: =TIME(R25,S25,0) -> 0.66041667

Sheet - H -
B1: Primera Fase
C4: PROGRAMA DE PARTIDOS | Q4: GRUPO H
H5: Sede | I5: día | K5: hora | M5: obs
B6: =IF(OR(M6="finalizado",M6="en juego",M6="hoy!"),"Ø","") | C6: =IF(R7<>"",R7,"") -> España | D6: 4 | E6: - | F6: 0 | G6: =IF(R9<>"",R9,"") -> Cabo Verde | H6: Atlanta | I6: 46188 | K6: 0.45833333 | M6: =IF(OR(I6="",K6="",I6<$R$24),"",IF(I6=$R$24,IF(AND(K6<=$S$26,$S$26<=(K6+0.08333333333)),"en juego",IF($S$26<K6,"hoy!","finalizado")),IF($R$24>I6,"finalizado","")))
B7: =IF(OR(M7="finalizado",M7="en juego",M7="hoy!"),"Ø","") | C7: =IF(R11<>"",R11,"") -> Arabia Saudí | D7: 0 | E7: - | F7: 1 | G7: =IF(R13<>"",R13,"") -> Uruguay | H7: Miami | I7: 46188 | K7: 0.70833333 | M7: =IF(OR(I7="",K7="",I7<$R$24),"",IF(I7=$R$24,IF(AND(K7<=$S$26,$S$26<=(K7+0.08333333333)),"en juego",IF($S$26<K7,"hoy!","finalizado")),IF($R$24>I7,"finalizado",""))) | R7: España
B8: =IF(OR(M8="finalizado",M8="en juego",M8="hoy!"),"Ø","") | C8: =IF(R7<>"",R7,"") -> España | D8: 2 | E8: - | F8: 0 | G8: =IF(R11<>"",R11,"") -> Arabia Saudí | H8: Atlanta | I8: 46194 | K8: 0.45833333 | M8: =IF(OR(I8="",K8="",I8<$R$24),"",IF(I8=$R$24,IF(AND(K8<=$S$26,$S$26<=(K8+0.08333333333)),"en juego",IF($S$26<K8,"hoy!","finalizado")),IF($R$24>I8,"finalizado","")))
B9: =IF(OR(M9="finalizado",M9="en juego",M9="hoy!"),"Ø","") | C9: =IF(R13<>"",R13,"") -> Uruguay | D9: 3 | E9: - | F9: 0 | G9: =IF(R9<>"",R9,"") -> Cabo Verde | H9: Miami | I9: 46194 | K9: 0.70833333 | M9: =IF(OR(I9="",K9="",I9<$R$24),"",IF(I9=$R$24,IF(AND(K9<=$S$26,$S$26<=(K9+0.08333333333)),"en juego",IF($S$26<K9,"hoy!","finalizado")),IF($R$24>I9,"finalizado",""))) | R9: Cabo Verde
B10: =IF(OR(M10="finalizado",M10="en juego",M10="hoy!"),"Ø","") | C10: =IF(R9<>"",R9,"") -> Cabo Verde | D10: 2 | E10: - | F10: 1 | G10: =IF(R11<>"",R11,"") -> Arabia Saudí | H10: Houston | I10: 46199 | K10: 0.79166667 | M10: =IF(OR(I10="",K10="",I10<$R$24),"",IF(I10=$R$24,IF(AND(K10<=$S$26,$S$26<=(K10+0.08333333333)),"en juego",IF($S$26<K10,"hoy!","finalizado")),IF($R$24>I10,"finalizado","")))
B11: =IF(OR(M11="finalizado",M11="en juego",M11="hoy!"),"Ø","") | C11: =IF(R13<>"",R13,"") -> Uruguay | D11: 0 | E11: - | F11: 1 | G11: =IF(R7<>"",R7,"") -> España | H11: Guadalajara | I11: 46199 | K11: 0.79166667 | M11: =IF(OR(I11="",K11="",I11<$R$24),"",IF(I11=$R$24,IF(AND(K11<=$S$26,$S$26<=(K11+0.08333333333)),"en juego",IF($S$26<K11,"hoy!","finalizado")),IF($R$24>I11,"finalizado",""))) | R11: Arabia Saudí
C13: =IF(OR(menu!$D$4="",menu!$D$6=""),"Atencion ! Aun te falta poner tu nombre y Pais en la hoja INICIO","") | R13: Uruguay
H15: POSICIONES
I16: J | J16: G | K16: E | L16: P | M16: GF | N16: GC | O16: DIF | P16: PTS
G17: Avanza a Dieciseisavos de final Ø | H17: =calculoH!F37 -> España | I17: =calculoH!G37 -> 3 | J17: =calculoH!H37 -> 3 | K17: =calculoH!I37 -> 0 | L17: =calculoH!J37 -> 0 | M17: =calculoH!K37 -> 7 | N17: =calculoH!L37 -> 0 | O17: =M17-N17 -> 7 | P17: =calculoH!M37 -> 9
G18: Avanza a Dieciseisavos de final Ø | H18: =calculoH!F38 -> Uruguay | I18: =calculoH!G38 -> 3 | J18: =calculoH!H38 -> 2 | K18: =calculoH!I38 -> 0 | L18: =calculoH!J38 -> 1 | M18: =calculoH!K38 -> 4 | N18: =calculoH!L38 -> 1 | O18: =M18-N18 -> 3 | P18: =calculoH!M38 -> 6
G19: =IF('- 3ros -'!$H$16=144,IF(VLOOKUP(H19,mejores3!$C$21:$T$32,18,0)=1,"Avanza como Mejor tercero: --> ",""),"") | H19: =calculoH!F39 -> Cabo Verde | I19: =calculoH!G39 -> 3 | J19: =calculoH!H39 -> 1 | K19: =calculoH!I39 -> 0 | L19: =calculoH!J39 -> 2 | M19: =calculoH!K39 -> 2 | N19: =calculoH!L39 -> 8 | O19: =M19-N19 -> -6 | P19: =calculoH!M39 -> 3
H20: =calculoH!F40 -> Arabia Saudí | I20: =calculoH!G40 -> 3 | J20: =calculoH!H40 -> 0 | K20: =calculoH!I40 -> 0 | L20: =calculoH!J40 -> 3 | M20: =calculoH!K40 -> 1 | N20: =calculoH!L40 -> 5 | O20: =M20-N20 -> -4 | P20: =calculoH!M40 -> 0
I21: =SUM(I17:I20) -> 12
Q24: fecha y hora actual: | R24: =TODAY() -> 46178 | S24: =NOW() -> 46178.661
R25: =HOUR(S24) -> 15 | S25: =MINUTE(S24) -> 51
S26: =TIME(R25,S25,0) -> 0.66041667

Sheet - I -
B1: Primera Fase
C4: PROGRAMA DE PARTIDOS | Q4: GRUPO I
H5: Sede | I5: día | K5: hora | M5: obs
B6: =IF(OR(M6="finalizado",M6="en juego",M6="hoy!"),"Ø","") | C6: =IF(R7<>"",R7,"") -> Francia | D6: 2 | E6: - | F6: 0 | G6: =IF(R9<>"",R9,"") -> Senegal | H6: Nueva York | I6: 46189 | K6: 0.58333333 | M6: =IF(OR(I6="",K6="",I6<$R$24),"",IF(I6=$R$24,IF(AND(K6<=$S$26,$S$26<=(K6+0.08333333333)),"en juego",IF($S$26<K6,"hoy!","finalizado")),IF($R$24>I6,"finalizado","")))
B7: =IF(OR(M7="finalizado",M7="en juego",M7="hoy!"),"Ø","") | C7: =IF(R11<>"",R11,"") -> Irak | D7: 0 | E7: - | F7: 2 | G7: =IF(R13<>"",R13,"") -> Noruega | H7: Boston | I7: 46189 | K7: 0.70833333 | M7: =IF(OR(I7="",K7="",I7<$R$24),"",IF(I7=$R$24,IF(AND(K7<=$S$26,$S$26<=(K7+0.08333333333)),"en juego",IF($S$26<K7,"hoy!","finalizado")),IF($R$24>I7,"finalizado",""))) | R7: Francia
B8: =IF(OR(M8="finalizado",M8="en juego",M8="hoy!"),"Ø","") | C8: =IF(R7<>"",R7,"") -> Francia | D8: 4 | E8: - | F8: 0 | G8: =IF(R11<>"",R11,"") -> Irak | H8: Filadelfia | I8: 46195 | K8: 0.66666667 | M8: =IF(OR(I8="",K8="",I8<$R$24),"",IF(I8=$R$24,IF(AND(K8<=$S$26,$S$26<=(K8+0.08333333333)),"en juego",IF($S$26<K8,"hoy!","finalizado")),IF($R$24>I8,"finalizado","")))
B9: =IF(OR(M9="finalizado",M9="en juego",M9="hoy!"),"Ø","") | C9: =IF(R13<>"",R13,"") -> Noruega | D9: 1 | E9: - | F9: 1 | G9: =IF(R9<>"",R9,"") -> Senegal | H9: Nueva York | I9: 46195 | K9: 0.79166667 | M9: =IF(OR(I9="",K9="",I9<$R$24),"",IF(I9=$R$24,IF(AND(K9<=$S$26,$S$26<=(K9+0.08333333333)),"en juego",IF($S$26<K9,"hoy!","finalizado")),IF($R$24>I9,"finalizado",""))) | R9: Senegal
B10: =IF(OR(M10="finalizado",M10="en juego",M10="hoy!"),"Ø","") | C10: =IF(R13<>"",R13,"") -> Noruega | D10: 1 | E10: - | F10: 3 | G10: =IF(R7<>"",R7,"") -> Francia | H10: Boston | I10: 46199 | K10: 0.58333333 | M10: =IF(OR(I10="",K10="",I10<$R$24),"",IF(I10=$R$24,IF(AND(K10<=$S$26,$S$26<=(K10+0.08333333333)),"en juego",IF($S$26<K10,"hoy!","finalizado")),IF($R$24>I10,"finalizado","")))
B11: =IF(OR(M11="finalizado",M11="en juego",M11="hoy!"),"Ø","") | C11: =IF(R9<>"",R9,"") -> Senegal | D11: 2 | E11: - | F11: 1 | G11: =IF(R11<>"",R11,"") -> Irak | H11: Toronto | I11: 46199 | K11: 0.58333333 | M11: =IF(OR(I11="",K11="",I11<$R$24),"",IF(I11=$R$24,IF(AND(K11<=$S$26,$S$26<=(K11+0.08333333333)),"en juego",IF($S$26<K11,"hoy!","finalizado")),IF($R$24>I11,"finalizado",""))) | R11: Irak
C13: =IF(OR(menu!$D$4="",menu!$D$6=""),"Atencion ! Aun te falta poner tu nombre y Pais en la hoja INICIO","") | R13: Noruega
H15: POSICIONES
I16: J | J16: G | K16: E | L16: P | M16: GF | N16: GC | O16: DIF | P16: PTS
G17: Avanza a Dieciseisavos de final Ø | H17: =calculoI!F37 -> Francia | I17: =calculoI!G37 -> 3 | J17: =calculoI!H37 -> 3 | K17: =calculoI!I37 -> 0 | L17: =calculoI!J37 -> 0 | M17: =calculoI!K37 -> 9 | N17: =calculoI!L37 -> 1 | O17: =M17-N17 -> 8 | P17: =calculoI!M37 -> 9
G18: Avanza a Dieciseisavos de final Ø | H18: =calculoI!F38 -> Noruega | I18: =calculoI!G38 -> 3 | J18: =calculoI!H38 -> 1 | K18: =calculoI!I38 -> 1 | L18: =calculoI!J38 -> 1 | M18: =calculoI!K38 -> 4 | N18: =calculoI!L38 -> 4 | O18: =M18-N18 -> 0 | P18: =calculoI!M38 -> 4
G19: =IF('- 3ros -'!$H$16=144,IF(VLOOKUP(H19,mejores3!$C$21:$T$32,18,0)=1,"Avanza como Mejor tercero: --> ",""),"") -> Avanza como Mejor tercero: --> | H19: =calculoI!F39 -> Senegal | I19: =calculoI!G39 -> 3 | J19: =calculoI!H39 -> 1 | K19: =calculoI!I39 -> 1 | L19: =calculoI!J39 -> 1 | M19: =calculoI!K39 -> 3 | N19: =calculoI!L39 -> 4 | O19: =M19-N19 -> -1 | P19: =calculoI!M39 -> 4
H20: =calculoI!F40 -> Irak | I20: =calculoI!G40 -> 3 | J20: =calculoI!H40 -> 0 | K20: =calculoI!I40 -> 0 | L20: =calculoI!J40 -> 3 | M20: =calculoI!K40 -> 1 | N20: =calculoI!L40 -> 8 | O20: =M20-N20 -> -7 | P20: =calculoI!M40 -> 0
I21: =SUM(I17:I20) -> 12
Q24: fecha y hora actual: | R24: =TODAY() -> 46178 | S24: =NOW() -> 46178.661
R25: =HOUR(S24) -> 15 | S25: =MINUTE(S24) -> 51
S26: =TIME(R25,S25,0) -> 0.66041667

Sheet - J -
B1: Primera Fase
C4: PROGRAMA DE PARTIDOS | Q4: GRUPO J
H5: Sede | I5: día | K5: hora | M5: obs
B6: =IF(OR(M6="finalizado",M6="en juego",M6="hoy!"),"Ø","") | C6: =IF(R7<>"",R7,"") -> Argentina | D6: 2 | E6: - | F6: 0 | G6: =IF(R9<>"",R9,"") -> Argelia | H6: Kansas City | I6: 46189 | K6: 0.83333333 | M6: =IF(OR(I6="",K6="",I6<$R$24),"",IF(I6=$R$24,IF(AND(K6<=$S$26,$S$26<=(K6+0.08333333333)),"en juego",IF($S$26<K6,"hoy!","finalizado")),IF($R$24>I6,"finalizado","")))
B7: =IF(OR(M7="finalizado",M7="en juego",M7="hoy!"),"Ø","") | C7: =IF(R11<>"",R11,"") -> Austria | D7: 2 | E7: - | F7: 1 | G7: =IF(R13<>"",R13,"") -> Jordania | H7: San Francisco | I7: 46189 | K7: 0.95833333 | M7: =IF(OR(I7="",K7="",I7<$R$24),"",IF(I7=$R$24,IF(AND(K7<=$S$26,$S$26<=(K7+0.08333333333)),"en juego",IF($S$26<K7,"hoy!","finalizado")),IF($R$24>I7,"finalizado",""))) | R7: Argentina
B8: =IF(OR(M8="finalizado",M8="en juego",M8="hoy!"),"Ø","") | C8: =IF(R7<>"",R7,"") -> Argentina | D8: 1 | E8: - | F8: 0 | G8: =IF(R11<>"",R11,"") -> Austria | H8: Dallas | I8: 46195 | K8: 0.5 | M8: =IF(OR(I8="",K8="",I8<$R$24),"",IF(I8=$R$24,IF(AND(K8<=$S$26,$S$26<=(K8+0.08333333333)),"en juego",IF($S$26<K8,"hoy!","finalizado")),IF($R$24>I8,"finalizado","")))
B9: =IF(OR(M9="finalizado",M9="en juego",M9="hoy!"),"Ø","") | C9: =IF(R13<>"",R13,"") -> Jordania | D9: 1 | E9: - | F9: 1 | G9: =IF(R9<>"",R9,"") -> Argelia | H9: San Francisco | I9: 46195 | K9: 0.91666667 | M9: =IF(OR(I9="",K9="",I9<$R$24),"",IF(I9=$R$24,IF(AND(K9<=$S$26,$S$26<=(K9+0.08333333333)),"en juego",IF($S$26<K9,"hoy!","finalizado")),IF($R$24>I9,"finalizado",""))) | R9: Argelia
B10: =IF(OR(M10="finalizado",M10="en juego",M10="hoy!"),"Ø","") | C10: =IF(R9<>"",R9,"") -> Argelia | D10: 0 | E10: - | F10: 2 | G10: =IF(R11<>"",R11,"") -> Austria | H10: Kansas City | I10: 46200 | K10: 0.875 | M10: =IF(OR(I10="",K10="",I10<$R$24),"",IF(I10=$R$24,IF(AND(K10<=$S$26,$S$26<=(K10+0.08333333333)),"en juego",IF($S$26<K10,"hoy!","finalizado")),IF($R$24>I10,"finalizado","")))
B11: =IF(OR(M11="finalizado",M11="en juego",M11="hoy!"),"Ø","") | C11: =IF(R13<>"",R13,"") -> Jordania | D11: 1 | E11: - | F11: 3 | G11: =IF(R7<>"",R7,"") -> Argentina | H11: Dallas | I11: 46200 | K11: 0.875 | M11: =IF(OR(I11="",K11="",I11<$R$24),"",IF(I11=$R$24,IF(AND(K11<=$S$26,$S$26<=(K11+0.08333333333)),"en juego",IF($S$26<K11,"hoy!","finalizado")),IF($R$24>I11,"finalizado",""))) | R11: Austria
C13: =IF(OR(menu!$D$4="",menu!$D$6=""),"Atencion ! Aun te falta poner tu nombre y Pais en la hoja INICIO","") | R13: Jordania
H15: POSICIONES
I16: J | J16: G | K16: E | L16: P | M16: GF | N16: GC | O16: DIF | P16: PTS
G17: Avanza a Dieciseisavos de final Ø | H17: =calculoJ!F37 -> Argentina | I17: =calculoJ!G37 -> 3 | J17: =calculoJ!H37 -> 3 | K17: =calculoJ!I37 -> 0 | L17: =calculoJ!J37 -> 0 | M17: =calculoJ!K37 -> 6 | N17: =calculoJ!L37 -> 1 | O17: =M17-N17 -> 5 | P17: =calculoJ!M37 -> 9
G18: Avanza a Dieciseisavos de final Ø | H18: =calculoJ!F38 -> Austria | I18: =calculoJ!G38 -> 3 | J18: =calculoJ!H38 -> 2 | K18: =calculoJ!I38 -> 0 | L18: =calculoJ!J38 -> 1 | M18: =calculoJ!K38 -> 4 | N18: =calculoJ!L38 -> 2 | O18: =M18-N18 -> 2 | P18: =calculoJ!M38 -> 6
G19: =IF('- 3ros -'!$H$16=144,IF(VLOOKUP(H19,mejores3!$C$21:$T$32,18,0)=1,"Avanza como Mejor tercero: --> ",""),"") | H19: =calculoJ!F39 -> Jordania | I19: =calculoJ!G39 -> 3 | J19: =calculoJ!H39 -> 0 | K19: =calculoJ!I39 -> 1 | L19: =calculoJ!J39 -> 2 | M19: =calculoJ!K39 -> 3 | N19: =calculoJ!L39 -> 6 | O19: =M19-N19 -> -3 | P19: =calculoJ!M39 -> 1
H20: =calculoJ!F40 -> Argelia | I20: =calculoJ!G40 -> 3 | J20: =calculoJ!H40 -> 0 | K20: =calculoJ!I40 -> 1 | L20: =calculoJ!J40 -> 2 | M20: =calculoJ!K40 -> 1 | N20: =calculoJ!L40 -> 5 | O20: =M20-N20 -> -4 | P20: =calculoJ!M40 -> 1
I21: =SUM(I17:I20) -> 12
Q24: fecha y hora actual: | R24: =TODAY() -> 46178 | S24: =NOW() -> 46178.661
R25: =HOUR(S24) -> 15 | S25: =MINUTE(S24) -> 51
S26: =TIME(R25,S25,0) -> 0.66041667

Sheet - K -
B1: Primera Fase
C4: PROGRAMA DE PARTIDOS | Q4: GRUPO K
H5: Sede | I5: día | K5: hora | M5: obs
B6: =IF(OR(M6="finalizado",M6="en juego",M6="hoy!"),"Ø","") | C6: =IF(R7<>"",R7,"") -> Portugal | D6: 4 | E6: - | F6: 0 | G6: =IF(R9<>"",R9,"") -> RD Congo | H6: Houston | I6: 46190 | K6: 0.5 | M6: =IF(OR(I6="",K6="",I6<$R$24),"",IF(I6=$R$24,IF(AND(K6<=$S$26,$S$26<=(K6+0.08333333333)),"en juego",IF($S$26<K6,"hoy!","finalizado")),IF($R$24>I6,"finalizado","")))
B7: =IF(OR(M7="finalizado",M7="en juego",M7="hoy!"),"Ø","") | C7: =IF(R11<>"",R11,"") -> Uzbekistán | D7: 0 | E7: - | F7: 3 | G7: =IF(R13<>"",R13,"") -> Colombia | H7: Ciudad de México | I7: 46190 | K7: 0.875 | M7: =IF(OR(I7="",K7="",I7<$R$24),"",IF(I7=$R$24,IF(AND(K7<=$S$26,$S$26<=(K7+0.08333333333)),"en juego",IF($S$26<K7,"hoy!","finalizado")),IF($R$24>I7,"finalizado",""))) | R7: Portugal
B8: =IF(OR(M8="finalizado",M8="en juego",M8="hoy!"),"Ø","") | C8: =IF(R7<>"",R7,"") -> Portugal | D8: 3 | E8: - | F8: 0 | G8: =IF(R11<>"",R11,"") -> Uzbekistán | H8: Houston | I8: 46196 | K8: 0.5 | M8: =IF(OR(I8="",K8="",I8<$R$24),"",IF(I8=$R$24,IF(AND(K8<=$S$26,$S$26<=(K8+0.08333333333)),"en juego",IF($S$26<K8,"hoy!","finalizado")),IF($R$24>I8,"finalizado","")))
B9: =IF(OR(M9="finalizado",M9="en juego",M9="hoy!"),"Ø","") | C9: =IF(R13<>"",R13,"") -> Colombia | D9: 2 | E9: - | F9: 0 | G9: =IF(R9<>"",R9,"") -> RD Congo | H9: Guadalajara | I9: 46196 | K9: 0.875 | M9: =IF(OR(I9="",K9="",I9<$R$24),"",IF(I9=$R$24,IF(AND(K9<=$S$26,$S$26<=(K9+0.08333333333)),"en juego",IF($S$26<K9,"hoy!","finalizado")),IF($R$24>I9,"finalizado",""))) | R9: RD Congo
B10: =IF(OR(M10="finalizado",M10="en juego",M10="hoy!"),"Ø","") | C10: =IF(R13<>"",R13,"") -> Colombia | D10: 1 | E10: - | F10: 2 | G10: =IF(R7<>"",R7,"") -> Portugal | H10: Miami | I10: 46200 | K10: 0.77083333 | M10: =IF(OR(I10="",K10="",I10<$R$24),"",IF(I10=$R$24,IF(AND(K10<=$S$26,$S$26<=(K10+0.08333333333)),"en juego",IF($S$26<K10,"hoy!","finalizado")),IF($R$24>I10,"finalizado","")))
B11: =IF(OR(M11="finalizado",M11="en juego",M11="hoy!"),"Ø","") | C11: =IF(R9<>"",R9,"") -> RD Congo | D11: 1 | E11: - | F11: 0 | G11: =IF(R11<>"",R11,"") -> Uzbekistán | H11: Atlanta | I11: 46200 | K11: 0.77083333 | M11: =IF(OR(I11="",K11="",I11<$R$24),"",IF(I11=$R$24,IF(AND(K11<=$S$26,$S$26<=(K11+0.08333333333)),"en juego",IF($S$26<K11,"hoy!","finalizado")),IF($R$24>I11,"finalizado",""))) | R11: Uzbekistán
C13: =IF(OR(menu!$D$4="",menu!$D$6=""),"Atencion ! Aun te falta poner tu nombre y Pais en la hoja INICIO","") | R13: Colombia
H15: POSICIONES
I16: J | J16: G | K16: E | L16: P | M16: GF | N16: GC | O16: DIF | P16: PTS
G17: Avanza a Dieciseisavos de final Ø | H17: =calculoK!F37 -> Portugal | I17: =calculoK!G37 -> 3 | J17: =calculoK!H37 -> 3 | K17: =calculoK!I37 -> 0 | L17: =calculoK!J37 -> 0 | M17: =calculoK!K37 -> 9 | N17: =calculoK!L37 -> 1 | O17: =M17-N17 -> 8 | P17: =calculoK!M37 -> 9
G18: Avanza a Dieciseisavos de final Ø | H18: =calculoK!F38 -> Colombia | I18: =calculoK!G38 -> 3 | J18: =calculoK!H38 -> 2 | K18: =calculoK!I38 -> 0 | L18: =calculoK!J38 -> 1 | M18: =calculoK!K38 -> 6 | N18: =calculoK!L38 -> 2 | O18: =M18-N18 -> 4 | P18: =calculoK!M38 -> 6
G19: =IF('- 3ros -'!$H$16=144,IF(VLOOKUP(H19,mejores3!$C$21:$T$32,18,0)=1,"Avanza como Mejor tercero: --> ",""),"") | H19: =calculoK!F39 -> RD Congo | I19: =calculoK!G39 -> 3 | J19: =calculoK!H39 -> 1 | K19: =calculoK!I39 -> 0 | L19: =calculoK!J39 -> 2 | M19: =calculoK!K39 -> 1 | N19: =calculoK!L39 -> 6 | O19: =M19-N19 -> -5 | P19: =calculoK!M39 -> 3
H20: =calculoK!F40 -> Uzbekistán | I20: =calculoK!G40 -> 3 | J20: =calculoK!H40 -> 0 | K20: =calculoK!I40 -> 0 | L20: =calculoK!J40 -> 3 | M20: =calculoK!K40 -> 0 | N20: =calculoK!L40 -> 7 | O20: =M20-N20 -> -7 | P20: =calculoK!M40 -> 0
I21: =SUM(I17:I20) -> 12
Q24: fecha y hora actual: | R24: =TODAY() -> 46178 | S24: =NOW() -> 46178.661
R25: =HOUR(S24) -> 15 | S25: =MINUTE(S24) -> 51
S26: =TIME(R25,S25,0) -> 0.66041667

Sheet - L -
B1: Primera Fase
C4: PROGRAMA DE PARTIDOS | Q4: GRUPO L
H5: Sede | I5: día | K5: hora | M5: obs
B6: =IF(OR(M6="finalizado",M6="en juego",M6="hoy!"),"Ø","") | C6: =IF(R7<>"",R7,"") -> Inglaterra | D6: 1 | E6: - | F6: 0 | G6: =IF(R9<>"",R9,"") -> Croacia | H6: Dallas | I6: 46190 | K6: 0.625 | M6: =IF(OR(I6="",K6="",I6<$R$24),"",IF(I6=$R$24,IF(AND(K6<=$S$26,$S$26<=(K6+0.08333333333)),"en juego",IF($S$26<K6,"hoy!","finalizado")),IF($R$24>I6,"finalizado","")))
B7: =IF(OR(M7="finalizado",M7="en juego",M7="hoy!"),"Ø","") | C7: =IF(R11<>"",R11,"") -> Ghana | D7: 1 | E7: - | F7: 0 | G7: =IF(R13<>"",R13,"") -> Panamá | H7: Toronto | I7: 46190 | K7: 0.75 | M7: =IF(OR(I7="",K7="",I7<$R$24),"",IF(I7=$R$24,IF(AND(K7<=$S$26,$S$26<=(K7+0.08333333333)),"en juego",IF($S$26<K7,"hoy!","finalizado")),IF($R$24>I7,"finalizado",""))) | R7: Inglaterra
B8: =IF(OR(M8="finalizado",M8="en juego",M8="hoy!"),"Ø","") | C8: =IF(R7<>"",R7,"") -> Inglaterra | D8: 2 | E8: - | F8: 0 | G8: =IF(R11<>"",R11,"") -> Ghana | H8: Boston | I8: 46196 | K8: 0.625 | M8: =IF(OR(I8="",K8="",I8<$R$24),"",IF(I8=$R$24,IF(AND(K8<=$S$26,$S$26<=(K8+0.08333333333)),"en juego",IF($S$26<K8,"hoy!","finalizado")),IF($R$24>I8,"finalizado","")))
B9: =IF(OR(M9="finalizado",M9="en juego",M9="hoy!"),"Ø","") | C9: =IF(R13<>"",R13,"") -> Panamá | D9: 1 | E9: - | F9: 3 | G9: =IF(R9<>"",R9,"") -> Croacia | H9: Toronto | I9: 46196 | K9: 0.75 | M9: =IF(OR(I9="",K9="",I9<$R$24),"",IF(I9=$R$24,IF(AND(K9<=$S$26,$S$26<=(K9+0.08333333333)),"en juego",IF($S$26<K9,"hoy!","finalizado")),IF($R$24>I9,"finalizado",""))) | R9: Croacia
B10: =IF(OR(M10="finalizado",M10="en juego",M10="hoy!"),"Ø","") | C10: =IF(R13<>"",R13,"") -> Panamá | D10: 0 | E10: - | F10: 3 | G10: =IF(R7<>"",R7,"") -> Inglaterra | H10: Nueva York | I10: 46200 | K10: 0.66666667 | M10: =IF(OR(I10="",K10="",I10<$R$24),"",IF(I10=$R$24,IF(AND(K10<=$S$26,$S$26<=(K10+0.08333333333)),"en juego",IF($S$26<K10,"hoy!","finalizado")),IF($R$24>I10,"finalizado","")))
B11: =IF(OR(M11="finalizado",M11="en juego",M11="hoy!"),"Ø","") | C11: =IF(R9<>"",R9,"") -> Croacia | D11: 2 | E11: - | F11: 1 | G11: =IF(R11<>"",R11,"") -> Ghana | H11: Filadelfia | I11: 46200 | K11: 0.66666667 | M11: =IF(OR(I11="",K11="",I11<$R$24),"",IF(I11=$R$24,IF(AND(K11<=$S$26,$S$26<=(K11+0.08333333333)),"en juego",IF($S$26<K11,"hoy!","finalizado")),IF($R$24>I11,"finalizado",""))) | R11: Ghana
C13: =IF(OR(menu!$D$4="",menu!$D$6=""),"Atencion ! Aun te falta poner tu nombre y Pais en la hoja INICIO","") | R13: Panamá
H15: POSICIONES
I16: J | J16: G | K16: E | L16: P | M16: GF | N16: GC | O16: DIF | P16: PTS
G17: Avanza a Dieciseisavos de final Ø | H17: =calculoL!F37 -> Inglaterra | I17: =calculoL!G37 -> 3 | J17: =calculoL!H37 -> 3 | K17: =calculoL!I37 -> 0 | L17: =calculoL!J37 -> 0 | M17: =calculoL!K37 -> 6 | N17: =calculoL!L37 -> 0 | O17: =M17-N17 -> 6 | P17: =calculoL!M37 -> 9
G18: Avanza a Dieciseisavos de final Ø | H18: =calculoL!F38 -> Croacia | I18: =calculoL!G38 -> 3 | J18: =calculoL!H38 -> 2 | K18: =calculoL!I38 -> 0 | L18: =calculoL!J38 -> 1 | M18: =calculoL!K38 -> 5 | N18: =calculoL!L38 -> 3 | O18: =M18-N18 -> 2 | P18: =calculoL!M38 -> 6
G19: =IF('- 3ros -'!$H$16=144,IF(VLOOKUP(H19,mejores3!$C$21:$T$32,18,0)=1,"Avanza como Mejor tercero: --> ",""),"") | H19: =calculoL!F39 -> Ghana | I19: =calculoL!G39 -> 3 | J19: =calculoL!H39 -> 1 | K19: =calculoL!I39 -> 0 | L19: =calculoL!J39 -> 2 | M19: =calculoL!K39 -> 2 | N19: =calculoL!L39 -> 4 | O19: =M19-N19 -> -2 | P19: =calculoL!M39 -> 3
H20: =calculoL!F40 -> Panamá | I20: =calculoL!G40 -> 3 | J20: =calculoL!H40 -> 0 | K20: =calculoL!I40 -> 0 | L20: =calculoL!J40 -> 3 | M20: =calculoL!K40 -> 1 | N20: =calculoL!L40 -> 7 | O20: =M20-N20 -> -6 | P20: =calculoL!M40 -> 0
I21: =SUM(I17:I20) -> 12
Q24: fecha y hora actual: | R24: =TODAY() -> 46178 | S24: =NOW() -> 46178.661
R25: =HOUR(S24) -> 15 | S25: =MINUTE(S24) -> 51
S26: =TIME(R25,S25,0) -> 0.66041667

Sheet - 3ros -
B1: Mejores T e r c e r o s
C4: Esta hoja es informativa… Continua a la siguiente Fase | Q4: Mejores 3ros
B6: =IF(OR(M6="finalizado",M6="en juego",M6="hoy!"),"Ø","") | C6: Estos son los 8 Mejores Terceros de la Fase Grupos según tus proyecciones 👍
B7: =IF(OR(M7="finalizado",M7="en juego",M7="hoy!"),"Ø","")
B8: =IF(OR(M8="finalizado",M8="en juego",M8="hoy!"),"Ø","")
B9: =IF(OR(M9="finalizado",M9="en juego",M9="hoy!"),"Ø","")
B10: =IF(OR(M10="finalizado",M10="en juego",M10="hoy!"),"Ø","")
B11: =IF(OR(M11="finalizado",M11="en juego",M11="hoy!"),"Ø","")
C13: =IF(H16<>144,"¡ Debes completar toda la Fase de Grupos para calcular los 8 mejores Terceros !","")
H15: 8 mejores Terceros:
H16: ='16vos de Final'!F3 -> 144 | I16: J | J16: G | K16: E | L16: P | M16: GF | N16: GC | O16: DIF | P16: PTS | Q16: Grupo:
G17: 1 Ø | H17: =IF($H$16=144,mejores3!C21,"") -> Korea | I17: =IF($H$16=144,mejores3!E21,"") -> 3 | J17: =IF($H$16=144,mejores3!F21,"") -> 1 | K17: =IF($H$16=144,mejores3!G21,"") -> 1 | L17: =IF($H$16=144,mejores3!H21,"") -> 1 | M17: =IF($H$16=144,mejores3!I21,"") -> 3 | N17: =IF($H$16=144,mejores3!J21,"") -> 3 | O17: =IF($H$16=144,mejores3!K21,"") -> 0 | P17: =IF($H$16=144,mejores3!L21,"") -> 4 | Q17: =IF($H$16=144,mejores3!B21,"") -> A
G18: 2 Ø | H18: =IF($H$16=144,mejores3!C22,"") -> Marruecos | I18: =IF($H$16=144,mejores3!E22,"") -> 3 | J18: =IF($H$16=144,mejores3!F22,"") -> 1 | K18: =IF($H$16=144,mejores3!G22,"") -> 1 | L18: =IF($H$16=144,mejores3!H22,"") -> 1 | M18: =IF($H$16=144,mejores3!I22,"") -> 2 | N18: =IF($H$16=144,mejores3!J22,"") -> 2 | O18: =IF($H$16=144,mejores3!K22,"") -> 0 | P18: =IF($H$16=144,mejores3!L22,"") -> 4 | Q18: =IF($H$16=144,mejores3!B22,"") -> C
G19: 3 Ø | H19: =IF($H$16=144,mejores3!C23,"") -> Irán | I19: =IF($H$16=144,mejores3!E23,"") -> 3 | J19: =IF($H$16=144,mejores3!F23,"") -> 1 | K19: =IF($H$16=144,mejores3!G23,"") -> 1 | L19: =IF($H$16=144,mejores3!H23,"") -> 1 | M19: =IF($H$16=144,mejores3!I23,"") -> 2 | N19: =IF($H$16=144,mejores3!J23,"") -> 2 | O19: =IF($H$16=144,mejores3!K23,"") -> 0 | P19: =IF($H$16=144,mejores3!L23,"") -> 4 | Q19: =IF($H$16=144,mejores3!B23,"") -> G
G20: 4 Ø | H20: =IF($H$16=144,mejores3!C24,"") -> Senegal | I20: =IF($H$16=144,mejores3!E24,"") -> 3 | J20: =IF($H$16=144,mejores3!F24,"") -> 1 | K20: =IF($H$16=144,mejores3!G24,"") -> 1 | L20: =IF($H$16=144,mejores3!H24,"") -> 1 | M20: =IF($H$16=144,mejores3!I24,"") -> 3 | N20: =IF($H$16=144,mejores3!J24,"") -> 4 | O20: =IF($H$16=144,mejores3!K24,"") -> -1 | P20: =IF($H$16=144,mejores3!L24,"") -> 4 | Q20: =IF($H$16=144,mejores3!B24,"") -> I
G21: 5 Ø | H21: =IF($H$16=144,mejores3!C25,"") -> Costa de Marfil | I21: =IF($H$16=144,mejores3!E25,"") -> 3 | J21: =IF($H$16=144,mejores3!F25,"") -> 1 | K21: =IF($H$16=144,mejores3!G25,"") -> 1 | L21: =IF($H$16=144,mejores3!H25,"") -> 1 | M21: =IF($H$16=144,mejores3!I25,"") -> 3 | N21: =IF($H$16=144,mejores3!J25,"") -> 5 | O21: =IF($H$16=144,mejores3!K25,"") -> -2 | P21: =IF($H$16=144,mejores3!L25,"") -> 4 | Q21: =IF($H$16=144,mejores3!B25,"") -> E
G22: 6 Ø | H22: =IF($H$16=144,mejores3!C26,"") -> Paraguay | I22: =IF($H$16=144,mejores3!E26,"") -> 3 | J22: =IF($H$16=144,mejores3!F26,"") -> 1 | K22: =IF($H$16=144,mejores3!G26,"") -> 0 | L22: =IF($H$16=144,mejores3!H26,"") -> 2 | M22: =IF($H$16=144,mejores3!I26,"") -> 2 | N22: =IF($H$16=144,mejores3!J26,"") -> 2 | O22: =IF($H$16=144,mejores3!K26,"") -> 0 | P22: =IF($H$16=144,mejores3!L26,"") -> 3 | Q22: =IF($H$16=144,mejores3!B26,"") -> D
G23: 7 Ø | H23: =IF($H$16=144,mejores3!C27,"") -> Bosnia | I23: =IF($H$16=144,mejores3!E27,"") -> 3 | J23: =IF($H$16=144,mejores3!F27,"") -> 1 | K23: =IF($H$16=144,mejores3!G27,"") -> 0 | L23: =IF($H$16=144,mejores3!H27,"") -> 2 | M23: =IF($H$16=144,mejores3!I27,"") -> 3 | N23: =IF($H$16=144,mejores3!J27,"") -> 4 | O23: =IF($H$16=144,mejores3!K27,"") -> -1 | P23: =IF($H$16=144,mejores3!L27,"") -> 3 | Q23: =IF($H$16=144,mejores3!B27,"") -> B
G24: 8 Ø | H24: =IF($H$16=144,mejores3!C28,"") -> Suecia | I24: =IF($H$16=144,mejores3!E28,"") -> 3 | J24: =IF($H$16=144,mejores3!F28,"") -> 1 | K24: =IF($H$16=144,mejores3!G28,"") -> 0 | L24: =IF($H$16=144,mejores3!H28,"") -> 2 | M24: =IF($H$16=144,mejores3!I28,"") -> 3 | N24: =IF($H$16=144,mejores3!J28,"") -> 4 | O24: =IF($H$16=144,mejores3!K28,"") -> -1 | P24: =IF($H$16=144,mejores3!L28,"") -> 3 | Q24: =IF($H$16=144,mejores3!B28,"") -> F
H25: =IF($H$16=144,mejores3!C29,"") -> Ghana | I25: =IF($H$16=144,mejores3!E29,"") -> 3 | J25: =IF($H$16=144,mejores3!F29,"") -> 1 | K25: =IF($H$16=144,mejores3!G29,"") -> 0 | L25: =IF($H$16=144,mejores3!H29,"") -> 2 | M25: =IF($H$16=144,mejores3!I29,"") -> 2 | N25: =IF($H$16=144,mejores3!J29,"") -> 4 | O25: =IF($H$16=144,mejores3!K29,"") -> -2 | P25: =IF($H$16=144,mejores3!L29,"") -> 3 | Q25: =IF($H$16=144,mejores3!B29,"") -> L
H26: =IF($H$16=144,mejores3!C30,"") -> RD Congo | I26: =IF($H$16=144,mejores3!E30,"") -> 3 | J26: =IF($H$16=144,mejores3!F30,"") -> 1 | K26: =IF($H$16=144,mejores3!G30,"") -> 0 | L26: =IF($H$16=144,mejores3!H30,"") -> 2 | M26: =IF($H$16=144,mejores3!I30,"") -> 1 | N26: =IF($H$16=144,mejores3!J30,"") -> 6 | O26: =IF($H$16=144,mejores3!K30,"") -> -5 | P26: =IF($H$16=144,mejores3!L30,"") -> 3 | Q26: =IF($H$16=144,mejores3!B30,"") -> K
H27: =IF($H$16=144,mejores3!C31,"") -> Cabo Verde | I27: =IF($H$16=144,mejores3!E31,"") -> 3 | J27: =IF($H$16=144,mejores3!F31,"") -> 1 | K27: =IF($H$16=144,mejores3!G31,"") -> 0 | L27: =IF($H$16=144,mejores3!H31,"") -> 2 | M27: =IF($H$16=144,mejores3!I31,"") -> 2 | N27: =IF($H$16=144,mejores3!J31,"") -> 8 | O27: =IF($H$16=144,mejores3!K31,"") -> -6 | P27: =IF($H$16=144,mejores3!L31,"") -> 3 | Q27: =IF($H$16=144,mejores3!B31,"") -> H
H28: =IF($H$16=144,mejores3!C32,"") -> Jordania | I28: =IF($H$16=144,mejores3!E32,"") -> 3 | J28: =IF($H$16=144,mejores3!F32,"") -> 0 | K28: =IF($H$16=144,mejores3!G32,"") -> 1 | L28: =IF($H$16=144,mejores3!H32,"") -> 2 | M28: =IF($H$16=144,mejores3!I32,"") -> 3 | N28: =IF($H$16=144,mejores3!J32,"") -> 6 | O28: =IF($H$16=144,mejores3!K32,"") -> -3 | P28: =IF($H$16=144,mejores3!L32,"") -> 1 | Q28: =IF($H$16=144,mejores3!B32,"") -> J
I29: =SUM(I17:I28) -> 36
R32: =TODAY() -> 46178 | S32: =NOW() -> 46178.661
R33: =HOUR(S32) -> 15 | S33: =MINUTE(S32) -> 51
S34: =TIME(R33,S33,0) -> 0.66041667

Sheet 16vos de Final
B1: Dieciseisavos de final | P1: Avance: | R1: =(16-SUM(R7:R67))/16 -> 1
F3: =SUM('- A -:- L -'!I21) -> 144
